Workbook

Sheet Summary
B2: DETAILED QUANTITY TAKEOFF — EXTERIOR ELECTRICAL & COMMUNICATIONS
B3: DOE Legacy Management — Site Improvement Package | 764 Horizon Dr., Grand Junction, CO
B4: Basis: 65% Submittal QC set (Kenall-FSC JV / HDR, issue date Sept 02 2026; elec sheets dated Feb 23 2026) — Contract W9128F24D0010. NOT FOR CONSTRUCTION.
B5: Scope per direction: EXTERIOR electrical & communications only (ES/E, TSN, TSY series + CD101 demo). Civil, wet utilities, fire protection & building interior systems excluded.
B7: TOTALS BY SYSTEM
B8: System | C8: Drawing Series | D8: Extension ($) | E8: Remarks
B9: Site Electrical (power, lighting, generator, service, demo) | C9: E-001, ES101, ES601, CD101 | D9: ='Site Electrical'!J42 -> 0 | E9: Utility primary & transformer by Xcel Energy; lighting branch circuits carried as allowance (not drawn at 65%).
B10: Telecommunications OSP (duct banks, MH/HH, fiber) | C10: TSN001, TSN100, TSN300, TSN400 | D10: ='Telecom OSP'!J40 -> 0 | E10: Duct bank lengths from plan dims where shown, otherwise scaled at 1"=30'. ISP cabling & pedestal by ISP.
B11: Security (access control, video intercom, gates) | C11: TSY001, TSY002, TSY100, TSY101 | D11: =Security!J37 -> 0 | E11: Video surveillance, intrusion detection, blue phones struck from matrix at 65% — excluded, verify.
B12: PROJECT TOTAL — EXTERIOR ELECTRICAL & COMM | D12: =SUM(D9:D11) -> 0
B14: HOW TO USE / LEGEND
B15: Yellow cells | C15: Enter your unit costs (material + labor) in the yellow 'Unit Cost' cells; extensions & totals compute automatically.
B16: Blue quantities | C16: Scaled from plan (1"=30') or carried as allowance — expect ±10-20% movement; firm up at 95%.
B17: Orange rows | C17: Open question / QC-comment risk — verify before bid (see notes column).
B18: Size & Type columns | C18: Sizes and types/materials/models are from drawing schedules & details; entries marked '(assumed)' or 'TBD' are not on the 65% drawings — confirm in specs or next submittal.
B19: Basis column | C19: Counted = symbol count from plan · Dimensioned = printed plan dimension · Scaled = measured at 1"=30' · Allowance = not shown at 65% · By Others-NIC = coordination only · Calc = formula-driven from other rows.
B20: Example | C20: e.g. Site Electrical item C1 (EA1 pole light): enter 12,500 in the yellow cell → extension shows $112,500 for 9 poles.
B22: KEY 65% DESIGN GAPS / QC COMMENTS AFFECTING QUANTITIES
B23: 1. Site photometric plan to be added (QC on ES101) — fixture counts/locations may change; one EA1 pole flagged for relocation (fire-truck access conflict near relocated generator).
B24: 2. Site lighting branch circuiting, panel sources & one-line references are not in the site set — carried as allowances; conduit/wire sizes assumed and so noted.
B25: 3. TSN100 duct bank overall dim 508'-8 3/4" at HH1-6 does not reconcile with segment dims (sums ±300 LF) — RFI recommended.
B26: 4. TSY002 matrix strikes video surveillance, intrusion detection, WAPs and blue phones, but TSY101 still shows VSS server / 'to building cameras' — confirm deletions.
B27: 5. Card reader locations updated per TSY100 at QC; gate-operator power JB may move closer to reader (ES101 QC).
B28: 6. Civil background on TSN100/TSY100 to be updated to most current — handhole/pedestal positions (HH1-1 labeling) to be confirmed.
B29: 7. OSP copper backbone questioned on TSN300 ('Where is the OSP copper?') — matrix lists it as contractor scope; allowance carried, pair count TBD.
B30: 8. Demarcation between Xcel Energy work and contract work to be documented in Design Analysis (QC on ES101) — primary work carried as NIC.
B31: 9. Luminaire schedule wattage/lumens/CCT columns largely blank at 65%; transformer kVA, generator kW, and secondary conductor sizes await one-line (building package).

Sheet Site Electrical
A1: SITE ELECTRICAL TAKEOFF (Sheets E-001, ES101, ES601 + CD101 demo)
A2: DOE Legacy Management – Site Improvement Package | 764 Horizon Dr., Grand Junction, CO | 65% Submittal (Issue 02 SEP 2026) | Contract W9128F24D0010
A4: Item | B4: Description | C4: Size | D4: Type / Material / Model No. | E4: Ref (Sheet / Detail / Keynote) | F4: Basis | G4: Qty | H4: Unit | I4: Unit Cost ($) | J4: Extension ($) | K4: Notes
A5: A. DEMOLITION / UTILITY COMPANY COORDINATION
A6: A1 | B6: Remove existing utility primary conduit & conductors back to splice point | C6: Size unknown (existing) | D6: Existing UG primary conduit & cable — remove & dispose | E6: ES101 / KN 2 | F6: Scaled | G6: 50 | H6: LF | J6: =IF(I6="","",G6*I6) | K6: Heavy-hatched route, splice point to existing transformer at Bldg A SW corner. Scaled at 1"=30' (±20%).
A7: A2 | B7: Existing utility transformer demolition — BY UTILITY (Xcel); coordination only | C7: — | D7: Existing pad-mount utility transformer | E7: ES101 / KN 9 | F7: By Others-NIC | G7: 1 | H7: EA | J7: =IF(I7="","",G7*I7) | K7: Demolished by utility company. Carry coordination/scheduling only.
A8: A3 | B8: Relocate existing government-owned generator to Building 'A' site, incl. all testing for manufacturer recertification | C8: Rating TBD (existing unit) | D8: Existing gov't-owned engine generator — rig, relocate, reconnect, recertify | E8: ES101 / KN 8 | F8: Counted | G8: 1 | H8: LS | J8: =IF(I8="","",G8*I8) | K8: Building EC responsible per KN 8. Nameplate/kW not shown in site set — confirm from building package.
A9: A4 | B9: Utility PRIMARY boring/trenching, conduit & wiring, splice point to new transformer — BY XCEL ENERGY | C9: Per XE standards | D9: Primary conduit & MV cable per Xcel Energy standards; 24" min trench, warning tape | E9: ES101 / KN 1,3,4; 1/ES601 | F9: By Others-NIC | G9: 150 | H9: LF | J9: =IF(I9="","",G9*I9) | K9: XE provides all primary conduit/wiring/trenching (KN 4). Route scaled ±150 LF for coordination. EC coordinates routing & termination.
A10: A5 | B10: Remove existing parking lot light pole and foundation (NW parking, Tract I) | C10: Height unknown (existing) | D10: Existing site light pole + concrete foundation — remove & dispose | E10: CD101 / KN 6 | F10: Counted | G10: 2 | H10: EA | J10: =IF(I10="","",G10*I10) | K10: 2 poles at KN 6 arrows. Note ES101 QC also flags relocating one NEW pole near generator — separate issue.
A11: A6 | B11: Remove existing underground electric line (UGE) serving demo'd poles | C11: Size unknown (existing) | D11: Existing UG electric branch — remove & dispose | E11: CD101 / KN 6, legend | F11: Scaled | G11: 200 | H11: LF | J11: =IF(I11="","",G11*I11) | K11: Between/beyond removed poles toward Bldg A. Scaled at 1"=30' (±25%).
A12: A7 | B12: Remove existing underground telephone line (T linetype) | C12: Size unknown (existing) | D12: Existing UG telephone cable/duct — remove & dispose | E12: CD101 legend | F12: Scaled | G12: 400 | H12: LF | J12: =IF(I12="","",G12*I12) | K12: Runs along north frontage/site. VERIFY ownership (telco may remove own plant) and limits.
A13: A8 | B13: Demolish existing electric meter | C13: — | D13: Existing utility meter — demolish, coordinate w/ XE | E13: CD101 legend (EM) | F13: Counted | G13: 1 | H13: EA | J13: =IF(I13="","",G13*I13) | K13: Legend item; symbol at Bldg A service area. Verify count at 95%.
A14: A9 | B14: Demolish existing communications junction box | C14: — | D14: Existing comm JB — demolish | E14: CD101 legend | F14: Counted | G14: 1 | H14: EA | J14: =IF(I14="","",G14*I14) | K14: Legend item; verify count. Comm pedestal at NW corner of Bldg C to be PROTECTED (QC fence-removal comment).
A15: A10 | B15: Protect in place: (2) existing transformers & pads, existing overhead power & poles (south boundary), comm pedestal at Bldg C | C15: — | D15: Temporary protection / barricades / coordination | E15: CD101 notes | F15: Counted | G15: 1 | H15: LS | J15: =IF(I15="","",G15*I15) | K15: Any utility damaged repaired at no additional cost (CD101 GN 1).
B16: Subtotal A | J16: =SUM(J6:J15) -> 0
A17: B. SERVICE & GENERATOR
A18: B1 | B18: New pad-mounted utility transformer — BY XCEL; coordination | C18: 480/277V, 3-phase (kVA TBD by XE) | D18: Pad-mount, XE-furnished & installed; XE makes primary & secondary connections | E18: ES101 / KN 4 | F18: By Others-NIC | G18: 1 | H18: EA | J18: =IF(I18="","",G18*I18) | K18: kVA sizing by utility from building load letter — not shown in site set.
A19: B2 | B19: Transformer concrete pad w/ clearances per XE | C19: Per XE standard dwg | D19: Cast-in-place concrete pad + ground grid per XE requirements | E19: ES101 / KN 4 | F19: Counted | G19: 1 | H19: EA | J19: =IF(I19="","",G19*I19) | K19: Pad by GC per KN 4 — coordinate pad & clearance requirements with XE.
A20: B3 | B20: Utility meter housing (furnish & install, coordinate w/ XE) + CT cabinet | C20: Per XE metering std | D20: Meter housing + CT cabinet, NEMA 3R; meter device by XE | E20: ES101 / KN 4 | F20: Counted | G20: 1 | H20: EA | J20: =IF(I20="","",G20*I20) | K20: EC furnishes & installs housing; XE furnishes/installs/connects meter.
A21: B4 | B21: UG secondary conduit system, transformer to Bldg A main service disconnect / MDP | C21: Conduit qty & size TBD per one-line | D21: PVC Sch 40 (assumed) w/ XHHW-2 Cu secondary conductors per one-line | E21: ES101 / KN 5 | F21: Scaled | G21: 30 | H21: LF | J21: =IF(I21="","",G21*I21) | K21: One-line is in building package — verify conduit count/size & conductor schedule at next submittal.
A22: B5 | B22: UG conduits, generator to automatic transfer switch(es) | C22: Conduit qty & size TBD per one-line | D22: PVC Sch 40 power + control (assumed); stub-ups field coordinated | E22: ES101 / KN 6 | F22: Scaled | G22: 50 | H22: LF | J22: =IF(I22="","",G22*I22) | K22: Refer to one-line for conduit count. Field coordinate exact routing & stub-up locations prior to rough-in (KN 6).
B23: Subtotal B | J23: =SUM(J18:J22) -> 0
A24: C. SITE LIGHTING (Schedule & details ES601)
A25: C1 | B25: Fixture EA1 — pole-mounted LED area light, Type 3 backlight control, glare shield, house-side shield, w/ pole | C25: 35' pole; 277V; 3000K, 80 CRI | D25: Lithonia DSX1-LED-P3-30K-80CRI-BLC3-MVOLT-PIR-SPD20KV-HS-EGSR-DDXX | E25: ES101/ES601 sched. | F25: Counted | G25: 9 | H25: EA | J25: =IF(I25="","",G25*I25) | K25: Tag count from plan. Integral PIR motion, dims to 30% after 10 min. Wattage/lumens columns blank in 65% schedule.
A26: C2 | B26: Fixture EA2 — pole-mounted LED area light, Type 5 wide distribution, glare shield, w/ pole | C26: 35' pole; 277V; 3000K, 80 CRI | D26: Lithonia DSX1-LED-P3-30K-80CRI-T5W-MVOLT-PIR-SPD20KV-EGSR-DDXX | E26: ES101/ES601 sched. | F26: Counted | G26: 7 | H26: EA | J26: =IF(I26="","",G26*I26) | K26: 7 tagged poles; plan symbols show TWIN heads on EA2 poles — verify heads/pole (14 luminaires if twin). Priced per pole assembly.
A27: C3 | B27: Fixture EA3 — pole-mounted LED area light, short-throw (T1S) distribution, glare shield, house-side shield, w/ pole | C27: 35' pole; 277V; 3000K, 80 CRI | D27: Lithonia DSX1-LED-P3-30K-80CRI-T1S-MVOLT-PIR-SPD20KV-HS-EGSR-DDXX | E27: ES101/ES601 sched. | F27: Counted | G27: 2 | H27: EA | J27: =IF(I27="","",G27*I27) | K27: Tag count from plan (east parking).
A28: C4 | B28: Pole base foundation w/ anchor bolts, grout, ground stud, handhole access | C28: 2'-0" dia. x 9'-6" deep | D28: CIP concrete (Div 03); 8-#5 vert., #4@10" ring ties; round in unpaved / square at paving | E28: 2/ES601 dim. sched. | F28: Counted | G28: 18 | H28: EA | J28: =IF(I28="","",G28*I28) | K28: 31'-40' pole row of dimension schedule governs for 35' poles.
A29: C5 | B29: Ground rod & pole bond | C29: 5/8" x 8' rod (assumed — not sized on dwg) | D29: Cu-clad steel rod; #6 AWG bare Cu bonded to rebar & pole ground stud | E29: 2/ES601 | F29: Counted | G29: 18 | H29: EA | J29: =IF(I29="","",G29*I29) | K29: One per pole base per detail. Rod size to be confirmed in Div 26 specs.
A30: C6 | B30: Fixture EB1 — exterior LED bollard (RADEAN), at grade | C30: 8-1/4" dia x 41-1/2" H; 277V; 3000K, 80 CRI | D30: RADB-LED-P1-30K-SYM-PIR-BTT-BCF-HXX-DDXX (schedule lists 'Luminis'; RADB is a Lithonia/Acuity RADEAN model — see RFI-13) | E30: ES101/ES601 sched. | F30: Counted | G30: 6 | H30: EA | J30: =IF(I30="","",G30*I30) | K30: 6 bollards along Bldg A south walk; integral PIR, symmetric distribution.
A31: C7 | B31: Bollard base foundation | C31: 1'-2" x depth per detail | D31: CIP concrete (Div 03); 4-#5 vert., #3 ties @10"; anchor bolts & leveling nuts per mfr | E31: 3/ES601 | F31: Counted | G31: 6 | H31: EA | J31: =IF(I31="","",G31*I31) | K31: Round foundation in unpaved areas; square in/adjacent to paving.
A32: C8 | B32: Fixture EF1 — exterior flagpole downlight, truck mounted | C32: Size M (flags to 15'x25'); 3000K; remote driver | D32: Eagle Mountain Flag & Flagpole 'StarGazer' SG-3K-EHS-M-XX (external-halyard stationary truck, dark-sky downlight) | E32: ES101/ES601 sched. | F32: Counted | G32: 3 | H32: EA | J32: =IF(I32="","",G32*I32) | K32: 3 at flagpoles NW of Bldg A. Schedule voltage column shows 0V at 65% — driver remote (see C9).
A33: C9 | B33: Weatherproof box w/ remote drivers for EF1 fixtures, buried in adjacent landscaped area | C33: NEMA 4/6P burial-rated (assumed) | D33: WP enclosure + (3) remote LED drivers | E33: ES101 / KN 10 | F33: Counted | G33: 1 | H33: EA | J33: =IF(I33="","",G33*I33) | K33: Field verify exact location of remote drivers prior to rough-in (KN 10).
A34: C10 | B34: Site lighting branch circuits — conduit, conductors & trench (ALLOWANCE — circuiting not shown at 65%) | C34: 1" PVC Sch 40 (assumed), 24" bury | D34: 2#10 + 1#10G Cu THWN-2 (assumed), 277V circuits; warning tape | E34: ES101 | F34: Allowance | G34: 2400 | H34: LF | J34: =IF(I34="","",G34*I34) | K34: No homeruns/circuit routing drawn at 65%; photometric plan to be added per QC. Allowance = pole-to-pole loop + homeruns; revise at 95%.
A35: C11 | B35: Lighting control interface — timeclock via lighting control panel in Bldg A | C35: — | D35: Control/interface wiring to LCP (panel in building package) | E35: ES601 seq. of ops | F35: Allowance | G35: 1 | H35: LS | J35: =IF(I35="","",G35*I35) | K35: Carry site interface/controls wiring allowance.
B36: Subtotal C | J36: =SUM(J25:J35) -> 0
A37: D. GATE OPERATOR POWER
A38: D1 | B38: Exterior-rated junction box, 120V power connection to exterior gate operator | C38: Size per NEC 314 (min 4-11/16" sq assumed) | D38: NEMA 3R/4 galvanized steel JB, stamped, gasketed | E38: ES101 / KN 7 | F38: Counted | G38: 3 | H38: EA | J38: =IF(I38="","",G38*I38) | K38: One at each vehicle gate (Bldg B west gate + 2 east gate pedestals). Verify exact locations w/ approved shop dwgs. QC: JB may shift closer to card reader.
A39: D2 | B39: Branch circuit to gate operator JBs (ALLOWANCE — source panel/routing not shown) | C39: 3/4" PVC (assumed conduit type) | D39: 2#10 + 1#10G Cu, 120V per KN 7 | E39: ES101 / KN 7 | F39: Allowance | G39: 700 | H39: LF | J39: =IF(I39="","",G39*I39) | K39: Conductors/size per KN 7; conduit material & source panel not indicated at 65%. Allowance for 3 runs.
B40: Subtotal D | J40: =SUM(J38:J39) -> 0
B42: SITE ELECTRICAL TOTAL | J42: =J16+J23+J36+J40 -> 0

Sheet Telecom OSP
A1: TELECOMMUNICATIONS OSP TAKEOFF (Sheets TSN001, TSN100, TSN300, TSN400)
A2: DOE Legacy Management – Site Improvement Package | 764 Horizon Dr., Grand Junction, CO | 65% Submittal (Issue 02 SEP 2026) | Contract W9128F24D0010
A4: Item | B4: Description | C4: Size | D4: Type / Material / Model No. | E4: Ref (Sheet / Detail / Keynote) | F4: Basis | G4: Qty | H4: Unit | I4: Unit Cost ($) | J4: Extension ($) | K4: Notes
A5: A. UNDERGROUND STRUCTURES
A6: A1 | B6: MH1 — telecom maintenance hole w/ cover, duct terminators/knockouts, bonding ribbon (4 plcs), sump | C6: 8'-0" L x 96" W x 96" H; 13" dia sump | D6: Precast concrete, 4260 base (9,275 lb) + 4260 top deck (2,100 lb), traffic-rated cover | E6: TSN100 sched.; H1/TSN400 | F6: Counted | G6: 4 | H6: EA | J6: =IF(I6="","",G6*I6) | K6: MH1-1 thru MH1-4. Provide knockouts to avoid 90° turns in duct bank (TSN400 note).
A7: A2 | B7: HH1 — telecom handhole | C7: 3'-0" L x 24" W x 48" H | D7: Polymer concrete box w/ slip-resistant polymer concrete cover, fasteners — NOT vehicle-traffic rated | E7: TSN100 sched.; A1/TSN400 | F7: Counted | G7: 5 | H7: EA | J7: =IF(I7="","",G7*I7) | K7: HH1-2 thru HH1-6 on TSN100. Install ≥5' from building perimeter (KN 2/3).
A8: A3 | B8: HH1-1 handhole (appears on TSY100 security plan only — VERIFY if additional) | C8: 3'-0" x 24" x 48" | D8: Polymer concrete (same as A2) | E8: TSY100 | F8: Counted | G8: 1 | H8: EA | J8: =IF(I8="","",G8*I8) | K8: TSY100 labels an HH1-1 near Horizon Dr. not tagged on TSN100 — confirm 6th handhole vs. re-label.
B9: Subtotal A | J9: =SUM(J6:J8) -> 0
A10: B. DUCT BANKS (schedule TSN100; sections TSN400)
A11: B1 | B11: DB1 duct bank — MH1-1 to ISP telecom pedestal (east along Horizon Dr.) | C11: (2) 4" conduits, 1H x 2W | D11: 4" PVC DB duct, ea. w/ (1) 4" 3-cell MaxCell innerduct; concrete-encased | E11: TSN100 / KN 1 | F11: Scaled | G11: 355 | H11: LF | J11: =IF(I11="","",G11*I11) | K11: Scaled at 1"=30' (±10%). ISP pedestal location approximate — coordinate w/ ISP.
A12: B2 | B12: DB1 duct bank — MH1-1 to MH1-2 | C12: (2) 4" conduits, 1H x 2W | D12: 4" PVC DB duct, ea. w/ (1) 4" 3-cell MaxCell innerduct; concrete-encased | E12: TSN100 | F12: Scaled | G12: 220 | H12: LF | J12: =IF(I12="","",G12*I12) | K12: Scaled at 1"=30' (±10%).
A13: B3 | B13: DB1 duct bank — MH1-2 to HH1-2 (Bldg C / pedestrian gate) | C13: (2) 4" conduits, 1H x 2W | D13: 4" PVC DB duct, ea. w/ (1) 4" 3-cell MaxCell innerduct; concrete-encased | E13: TSN100 / KN 3 | F13: Scaled | G13: 165 | H13: LF | J13: =IF(I13="","",G13*I13) | K13: Future conduit connection to Bldg C; coordinate final HH location w/ security contractor.
A14: B4 | B14: DB1 duct bank — MH1-2 to HH1-4 (Bldg B) | C14: (2) 4" conduits, 1H x 2W | D14: 4" PVC DB duct, ea. w/ (1) 4" 3-cell MaxCell innerduct; concrete-encased | E14: TSN100 / KN 4 | F14: Scaled | G14: 90 | H14: LF | J14: =IF(I14="","",G14*I14) | K14: Coordinate final location w/ security contractor for connection to security gate.
A15: B5 | B15: DB1 duct bank — MH1-3 to MH1-4 | C15: (2) 4" conduits, 1H x 2W | D15: 4" PVC DB duct, ea. w/ (1) 4" 3-cell MaxCell innerduct; concrete-encased | E15: TSN100 | F15: Dimensioned | G15: 123.1 | H15: LF | J15: =IF(I15="","",G15*I15) | K15: Plan dim 123'-1".
A16: B6 | B16: DB1 duct bank — MH1-4 to HH1-3 (future Bldg B connection) | C16: (2) 4" conduits, 1H x 2W | D16: 4" PVC DB duct, ea. w/ (1) 4" 3-cell MaxCell innerduct; concrete-encased | E16: TSN100 / KN 2 | F16: Dimensioned | G16: 13.7 | H16: LF | J16: =IF(I16="","",G16*I16) | K16: Plan dim 13'-8 1/4".
A17: B7 | B17: DB1 SUBTOTAL — (2) 4" PVC w/ MaxCell | G17: =SUM(G11:G16) -> 966.8 | H17: LF
A18: B8 | B18: DB2 duct bank — MH1-2 to MH1-3 | C18: (4) 4" conduits, 2H x 2W | D18: 4" PVC DB duct, ea. w/ (1) 4" 3-cell MaxCell innerduct; concrete-encased | E18: TSN100 | F18: Scaled | G18: 120 | H18: LF | J18: =IF(I18="","",G18*I18) | K18: Scaled at 1"=30' (±10%).
A19: B9 | B19: DB2 duct bank — MH1-3 to Bldg A entry | C19: (4) 4" conduits, 2H x 2W | D19: 4" PVC DB duct, ea. w/ (1) 4" 3-cell MaxCell innerduct; concrete-encased | E19: TSN100 | F19: Dimensioned | G19: 21.4 | H19: LF | J19: =IF(I19="","",G19*I19) | K19: Plan dim 21'-4 3/4" to building; additional 33'-10 3/4" continues inside Bldg A (building package).
A20: B10 | B20: DB2 SUBTOTAL — (4) 4" PVC w/ MaxCell | G20: =SUM(G18:G19) -> 141.4 | H20: LF
A21: B11 | B21: DB3 duct bank — HH1-3 to HH1-5 | C21: (2) 2" conduits, 1H x 2W | D21: 2" PVC duct, ea. w/ (1) 2" 3-cell MaxCell innerduct; encasement assumed (no section) | E21: TSN100 | F21: Dimensioned | G21: 101.5 | H21: LF | J21: =IF(I21="","",G21*I21) | K21: 72'-x 1/4" diagonal + 29'-2 1/2" segments (partially obscured dim — verify 72' leg).
A22: B12 | B22: DB3 duct bank — HH1-5 to HH1-6 (east vehicle gate) | C22: (2) 2" conduits, 1H x 2W | D22: 2" PVC duct, ea. w/ (1) 2" 3-cell MaxCell innerduct; encasement assumed (no section) | E22: TSN100 | F22: Dimensioned | G22: 197.3 | H22: LF | J22: =IF(I22="","",G22*I22) | K22: 179'-7 1/4" + 17'-8 3/4". NOTE: overall dim 508'-8 3/4" also shown at HH1-6 does NOT reconcile — RFI.
A23: B13 | B23: DB3 SUBTOTAL — (2) 2" PVC w/ MaxCell | G23: =SUM(G21:G22) -> 298.8 | H23: LF
B24: Subtotal B (priced lines) | J24: =SUM(J11:J23) -> 0
A25: C. TRENCH / ENCASEMENT / MISC (quantities driven by duct bank LF above)
A26: C1 | B26: Trench & backfill for telecom duct banks | C26: 30" min cover; ≥6' deep under traffic | D26: Excavate, bed, backfill, compact; detectable warning tape; below 50-yr freeze line | E26: TSN100 GN 8/9 | F26: Calc | G26: =SUM(G11:G16)+SUM(G18:G19)+SUM(G21:G22) -> 1407 | H26: LF | J26: =IF(I26="","",G26*I26) | K26: Equals sum of all duct bank segments above.
A27: C2 | B27: Concrete encasement — DB1 runs | C27: 16" H x 23" W section (2.56 SF) | D27: 3000 psi concrete; 4-#4 longitudinal rebar; #3 wire hoops @18" OC; plastic spacers @4' OC | E27: A8/TSN400 | F27: Calc | G27: =ROUND(SUM(G11:G16)*2.56/27,1) -> 91.7 | H27: CY | J27: =IF(I27="","",G27*I27) | K27: Qty = DB1 LF x 2.56 SF / 27. Reinforcement may vary w/ soil conditions per structural.
A28: C3 | B28: Concrete encasement — DB2 runs | C28: 25" x 25" section (4.34 SF) | D28: 3000 psi concrete; 4-#4 longitudinal rebar; #3 wire hoops @18" OC; plastic spacers @4' OC | E28: A13/TSN400 | F28: Calc | G28: =ROUND(SUM(G18:G19)*4.34/27,1) -> 22.7 | H28: CY | J28: =IF(I28="","",G28*I28) | K28: Qty = DB2 LF x 4.34 SF / 27.
A29: C4 | B29: Concrete encasement — DB3 runs (assumed encased; no section drawn) | C29: 14" x 8-1/2" envelope (0.83 SF) | D29: 3000 psi concrete (assumed, matching DB1/DB2) | E29: TSN100 sched. | F29: Calc | G29: =ROUND(SUM(G21:G22)*0.83/27,1) -> 9.2 | H29: CY | J29: =IF(I29="","",G29*I29) | K29: Qty = DB3 LF x 0.83 SF / 27. Verify concrete-encased vs. direct-buried (RFI-2).
A30: C5 | B30: Bonding conductor, power-to-telecom plant bond; bond metallic-sheath cables at each MH | C30: #6 AWG min | D30: Bare Cu bonding conductor per NEC/NESC (IEEE C2); MH bonding ribbon connections | E30: TSN100 GN 3/12 | F30: Allowance | G30: 1 | H30: LS | J30: =IF(I30="","",G30*I30)
A31: C6 | B31: Pull string / mule tape in all conduits & innerduct cells | C31: — | D31: Polyester mule tape, 1,250 lb (assumed); empty conduits w/ 200-lb test pull string per TSN notes | E31: TSN gen. notes | F31: Allowance | G31: 1 | H31: LS | J31: =IF(I31="","",G31*I31)
B32: Subtotal C | J32: =SUM(J26:J31) -> 0
A33: D. OSP CABLING (TSN300 site one-line)
A34: D1 | B34: OSP fiber — Bldg A to MH/HH system incl. coils for future connection at Bldg B/C and east gate handholes | C34: 12-strand | D34: OM4 50/125 multimode, OSP-rated (gel-free, assumed), green-dashed runs per TSN300 | E34: TSN300 | F34: Scaled | G34: 1600 | H34: LF | J34: =IF(I34="","",G34*I34) | K34: Routes + 20% slack + coils (QC: coiled for future connection at HH1s). Revise when cable schedule issued.
A35: D2 | B35: Fiber terminations, LIU/patch panel at Bldg A, testing & documentation | C35: 12 strands | D35: LC LIU/patch panel (assumed); OTDR + insertion loss testing, labeling per TIA-606 | E35: TSN300; TSN001 matrix | F35: Allowance | G35: 1 | H35: LS | J35: =IF(I35="","",G35*I35) | K35: Contractor per responsibility matrix (Div 27).
A36: D3 | B36: OSP copper backbone cabling — TBD (QC: 'Where is the OSP copper?') | C36: Pair count TBD | D36: OSP-rated copper backbone (type/size not shown at 65%) | E36: TSN300 QC | F36: Allowance | G36: 1 | H36: LS | J36: =IF(I36="","",G36*I36) | K36: Matrix lists copper backbone as Contractor scope but none shown on one-line — carry allowance / RFI.
A37: D4 | B37: ISP fiber & ISP telecom pedestal — BY ISP | C37: Per ISP | D37: ISP-furnished fiber & pedestal; contractor provides DB1 pathway (item B1) | E37: TSN300; TSN001 matrix | F37: By Others-NIC | G37: 1 | H37: LS | J37: =IF(I37="","",G37*I37)
B38: Subtotal D | J38: =SUM(J34:J37) -> 0
B40: TELECOM OSP TOTAL | J40: =J9+J24+J32+J38 -> 0

Sheet Security
A1: SECURITY SYSTEMS TAKEOFF (Sheets TSY001, TSY002, TSY100, TSY101)
A2: DOE Legacy Management – Site Improvement Package | 764 Horizon Dr., Grand Junction, CO | 65% Submittal (Issue 02 SEP 2026) | Contract W9128F24D0010
A4: Item | B4: Description | C4: Size | D4: Type / Material / Model No. | E4: Ref (Sheet / Detail / Keynote) | F4: Basis | G4: Qty | H4: Unit | I4: Unit Cost ($) | J4: Extension ($) | K4: Notes
A5: A. FIELD DEVICES — GATES
A6: A1 | B6: Pedestal-mounted video intercom w/ integrated card reader, concrete footer & conduit | C6: 48" above roadway; min 2" sq pedestal | D6: Welded 316 stainless gooseneck pedestal, heavy wall; PoE video intercom + reader; 1" conduit for signal; footer to frost depth, 20" from curb | E6: TSY100; A1/TSY101 | F6: Counted | G6: 2 | H6: EA | J6: =IF(I6="","",G6*I6) | K6: East vehicle gates at HH1-5 & HH1-6. QC: locations updated per civil — verify against updated background.
A7: A2 | B7: Building-mounted video intercom w/ integrated card reader — vehicle gate at Bldg B | C7: Mtg ht 3'-10" AFF (typ per TSY001) | D7: Wall-mount video intercom/reader; 4-11/16" sq 2-device mud-ring box, 2-1/8" deep; (1) 1" C stub | E7: TSY100; TSY001 sched. | F7: Counted | G7: 1 | H7: EA | J7: =IF(I7="","",G7*I7)
A8: A3 | B8: Building-mounted card reader — pedestrian gate (Bldg C area) | C8: Mtg ht 3'-6" AFF (typ per TSY001) | D8: Card reader; 4-11/16" sq 1-device mud-ring box, 2-1/8" deep; (1) 3/4" C stub | E8: TSY100; TSY001 sched. | F8: Counted | G8: 1 | H8: EA | J8: =IF(I8="","",G8*I8) | K8: QC: shift reader to wall mount at the gate; OSP-rated ACS cable keynote to be added.
A9: A4 | B9: Card reader at personnel swing gate (TSY101 inset, KN 7) — additional to A3? | C9: Mtg ht 3'-6" AFF (typ) | D9: Card reader in WP enclosure (see A8 rough-in) | E9: TSY101 inset KN 7-9 | F9: Counted | G9: 1 | H9: EA | J9: =IF(I9="","",G9*I9) | K9: Inset shows readers at swing gate (KN 8) & personnel swing gate (KN 9, gates per C-503). VERIFY overlap with A2/A3 before pricing.
A10: A5 | B10: Vehicle gate operator connection/interface (operator & gate by others — civil C-503) | C10: — | D10: Gate command wiring, dry-contact/relay interface to operator controller | E10: TSY101 flow diag. | F10: Counted | G10: 3 | H10: EA | J10: =IF(I10="","",G10*I10) | K10: VEH GATE 1/2/3 operators. 120V power JB by electrical (Site Electrical D1).
A11: A6 | B11: Vehicle exit loop w/ lead-in to gate operator | C11: Loop size per operator mfr | D11: Preformed or saw-cut inductive loop + sealant + lead-in | E11: TSY101 flow diag. | F11: Counted | G11: 3 | H11: EA | J11: =IF(I11="","",G11*I11)
A12: A7 | B12: Gate position switch (DPS) on sliding gate | C12: — | D12: Magnet on gate + position switch on fence-post bracket; armored cable; WP single-gang box; 3/4" conduit to handhole | E12: A7/TSY101 | F12: Counted | G12: 3 | H12: EA | J12: =IF(I12="","",G12*I12) | K12: Assumed one per vehicle gate; verify sliding vs. swing gate count w/ C-503.
A13: A8 | B13: Access control rough-in at fence gates | C13: (2) 1" conduits to SEC | D13: WP sheet-metal enclosure for card reader; swinging gate lock & bracket; torx/peg tamper-resistant hardware | E13: A13/TSY101; GN 18 | F13: Counted | G13: 2 | H13: EA | J13: =IF(I13="","",G13*I13) | K13: Per access control gate rough-in detail (swing/personnel gates).
B14: Subtotal A | J14: =SUM(J6:J13) -> 0
A15: B. HEAD END (COMM 124, Bldg A) & PANELS
A16: B1 | B16: Access control panel ACP1 | C16: Surface mount, 5'-0" AFF (TSY001 sched.) | D16: ACP w/ enclosure & power supply, Div 28; mount to fire-rated plywood | E16: G2/TSY101; TSY001 | F16: Counted | G16: 1 | H16: EA | J16: =IF(I16="","",G16*I16)
A17: B2 | B17: Access control panel ACP2 ('if necessary') | C17: Surface mount, 5'-0" AFF | D17: ACP w/ enclosure & power supply, Div 28 | E17: G2/TSY101 | F17: Counted | G17: 1 | H17: EA | J17: =IF(I17="","",G17*I17) | K17: Shown dashed / 'IF NECESSARY' — carry until panel count confirmed.
A18: B3 | B18: Equipment rack, COMM 124 | C18: 12U | D18: Wall/floor rack per detail | E18: G2/TSY101 | F18: Counted | G18: 1 | H18: EA | J18: =IF(I18="","",G18*I18)
A19: B4 | B19: ACS server + access control software, licensing & commissioning | C19: Rack-mount | D19: ACS server, Div 28 contractor furnished/installed per matrix | E19: G2/TSY101; TSY002 | F19: Counted | G19: 1 | H19: LS | J19: =IF(I19="","",G19*I19)
A20: B5 | B20: VIC (video intercom) master station | C20: Desktop (TSY001 sched.) | D20: Video intercom master station w/ (1) copper cable to switch; surface mount to desk | E20: TSY101 flow diag. | F20: Counted | G20: 1 | H20: EA | J20: =IF(I20="","",G20*I20) | K20: Video intercom system remains contractor scope per TSY002.
A21: B6 | B21: Security network switch — OWNER furnished/installed; coordination only | C21: PoE | D21: Owner network switch (matrix: owner/owner) | E21: TSY002 matrix | F21: By Others-NIC | G21: 1 | H21: EA | J21: =IF(I21="","",G21*I21)
A22: B7 | B22: VSS (video surveillance) server — EXCLUDED (struck from TSY002 at 65%) | C22: — | D22: — | E22: TSY002 | F22: Excluded | G22: 0 | H22: EA | K22: VSS head-end, cameras & cabling struck on matrix but still drawn on G2/TSY101 rack — VERIFY deletion before bid.
A23: B8 | B23: Surge protection devices & associated cabling (head end + field) | C23: — | D23: SPDs on OSP copper entering building + device circuits, Div 28 | E23: TSY002 | F23: Allowance | G23: 1 | H23: LS | J23: =IF(I23="","",G23*I23)
B24: Subtotal B | J24: =SUM(J16:J23) -> 0
A25: C. CABLING (homeruns via telecom duct bank system to COMM 124)
A26: C1 | B26: OSP-rated access control cable to each card reader location | C26: Composite/multi-conductor per spec 28 | D26: OSP-rated ACS cable (reader/lock/DPS/REX composite assumed) | E26: TSY100 QC notes | F26: Allowance | G26: 1800 | H26: LF | J26: =IF(I26="","",G26*I26) | K26: 5 reader locations; homerun lengths estimated along duct routes + slack.
A27: C2 | B27: Extended-reach copper data cable to each intercom (3) | C27: 4-pair, 22 AWG min | D27: Extended-reach PoE-rated OSP copper data cable (per TSY101 riser note & QC keynote) | E27: TSY101; TSY100 QC | F27: Allowance | G27: 1400 | H27: LF | J27: =IF(I27="","",G27*I27) | K27: (3) cables per riser note. Verify length/bandwidth/PoE load/voltage-drop per mfr (GN 9) — east gate run ±600 LF.
A28: C3 | B28: ACS cables, ACP1/ACP2 to Bldg A doors/monitored devices — BUILDING PACKAGE | C28: — | D28: — | E28: G2/TSY101 | F28: By Others-NIC | G28: 0 | H28: LS | K28: Interior building security in Building A package, excluded from site takeoff.
A29: C4 | B29: Testing, labeling, commissioning, software licensing — all site security systems; record drawings | C29: — | D29: Per TSY100 GN 8 & Div 28 | E29: TSY002; TSY100 GN 8 | F29: Allowance | G29: 1 | H29: LS | J29: =IF(I29="","",G29*I29)
B30: Subtotal C | J30: =SUM(J26:J29) -> 0
A31: D. EXCLUSIONS (struck from TSY002 responsibility matrix at 65% — VERIFY)
A32: D1 | B32: Video surveillance cameras, mounting hardware, network cabling, head-end server & storage | C32: — | D32: — | E32: TSY002 | F32: Excluded | G32: 0 | H32: — | K32: Struck through in red on matrix.
A33: D2 | B33: Intrusion detection system (head end, DPS/glass break/motion devices, cabling) | C33: — | D33: — | E33: TSY002 | F33: Excluded | G33: 0 | H33: — | K33: Struck through in red on matrix.
A34: D3 | B34: Wireless access points & enclosures; servers/routers/firewalls/phones/computers | C34: — | D34: — | E34: TSY002 | F34: Excluded | G34: 0 | H34: — | K34: Owner items / struck.
A35: D4 | B35: Emergency blue phones & associated cabling | C35: — | D35: — | E35: TSY002 | F35: Excluded | G35: 0 | H35: — | K35: Struck through in red on matrix.
B37: SECURITY TOTAL | J37: =J14+J24+J30 -> 0

Sheet Materials & Makes
A1: MATERIALS, MAKES & MODELS — PROCUREMENT LIST
A2: 'Specified' = named on the 65% drawings. 'Basis-of-design (suggested)' = drawings silent — a common product meeting the drawn requirements, offered for pricing only; Div 26/27/28 specs govern. Qty cells link live to the takeoff tabs.
A4: Cat. | B4: Item | C4: Size / Rating | D4: Manufacturer | E4: Model / Part No. | F4: Spec Status | G4: Qty | H4: Unit | I4: Notes
A5: LIGHTING
A6: L1 | B6: Area luminaire EA1 (Type 3, backlight control, house-side shield) | C6: 35' pole mt; 277V; 3000K/80CRI; P3 pkg | D6: Lithonia Lighting (Acuity) | E6: DSX1-LED-P3-30K-80CRI-BLC3-MVOLT-XXXX-PIR-SPD20KV-HS-EGSR-DDXX | F6: Specified | G6: ='Site Electrical'!G25 -> 9 | H6: EA | I6: D-Series Size 1. Wattage/lumen columns blank on 65% schedule — per fixture submittal. XXXX = distribution/finish fields to complete.
A7: L2 | B7: Area luminaire EA2 (Type 5 wide) | C7: 35' pole mt; 277V; 3000K/80CRI; P3 pkg | D7: Lithonia Lighting (Acuity) | E7: DSX1-LED-P3-30K-80CRI-T5W-MVOLT-XXXX-PIR-SPD20KV-EGSR-DDXX | F7: Specified | G7: ='Site Electrical'!G26 -> 7 | H7: EA | I7: Plan symbol shows twin heads/pole — RFI-3.
A8: L3 | B8: Area luminaire EA3 (short-throw T1S, house-side shield) | C8: 35' pole mt; 277V; 3000K/80CRI; P3 pkg | D8: Lithonia Lighting (Acuity) | E8: DSX1-LED-P3-30K-80CRI-T1S-MVOLT-XXXX-PIR-SPD20KV-HS-EGSR-DDXX | F8: Specified | G8: ='Site Electrical'!G27 -> 2 | H8: EA
A9: L4 | B9: Light pole, round straight steel or aluminum | C9: 35'-0 nominal; drilled for D-Series arm | D9: Valmont / RSA / Lithonia SSS (or equal) | E9: Per luminaire mfr pole selector, EPA per wind load | F9: TBD | G9: 18 | H9: EA | I9: Pole make/finish NOT scheduled at 65% — coordinate w/ luminaire order; anchor bolts per mfr (2/ES601).
A10: L5 | B10: LED bollard EB1 (RADEAN) | C10: 8-1/4" dia x 41-1/2" H; 277V; 3000K/80CRI | D10: Lithonia Lighting (Acuity) — schedule says 'Luminis' | E10: RADB-LED-P1-30K-SYM-PIR-BTT-BCF-HXX-DDXX | F10: Specified | G10: ='Site Electrical'!G30 -> 6 | H10: EA | I10: RADB is Lithonia's RADEAN bollard (Luminis is a sister Acuity brand) — RFI-13 to correct schedule mfr.
A11: L6 | B11: Flagpole downlight EF1 (StarGazer) | C11: Size M (flags to 15'x25'); 3000K; LED | D11: Eagle Mountain Flag & Flagpole | E11: SG-3K-EHS-M-XX (external halyard, stationary truck) | F11: Specified | G11: ='Site Electrical'!G32 -> 3 | H11: EA | I11: Dark-sky downlight; remote drivers in buried WP box (ES101 KN 10).
A12: L7 | B12: WP enclosure for EF1 remote drivers | C12: Burial/landscape rated, NEMA 4/6P (assumed) | D12: TBD (per driver mfr) | E12: — | F12: TBD | G12: ='Site Electrical'!G33 -> 1 | H12: EA | I12: Verify enclosure & driver model w/ Eagle Mountain submittal.
A13: SERVICE & POWER
A14: P1 | B14: Pad-mount transformer | C14: 480/277V 3-ph; kVA TBD by utility | D14: Xcel Energy | E14: Per XE standards | F14: By Others | G14: 1 | H14: EA | I14: XE furnished/installed; pad & grounding by GC/EC.
A15: P2 | B15: Meter housing + CT cabinet | C15: Per XE metering standard; NEMA 3R | D15: Milbank / B-Line (or per XE approved list) | E15: Per XE metering spec | F15: BOD (suggested) | G15: ='Site Electrical'!G20 -> 1 | H15: EA | I15: EC furnishes/installs housing; XE sets meter (ES101 KN 4).
A16: P3 | B16: Exterior JB for gate operator power | C16: Min 4-11/16" sq (NEC 314); NEMA 3R/4 | D16: Hoffman / Wiegmann (or equal) | E16: Galvanized steel, gasketed, stamped | F16: BOD (suggested) | G16: ='Site Electrical'!G38 -> 3 | H16: EA | I16: Per ES101 KN 7; 2#10+1#10G, 3/4"C, 120V.
A17: P4 | B17: Ground rods & bonding | C17: 5/8" x 8' (assumed); #6 bare Cu | D17: ERICO / Harger (or equal) | E17: Cu-clad rod + exothermic or irreversible compression | F17: BOD (suggested) | G17: ='Site Electrical'!G29 -> 18 | H17: EA | I17: Rod size not on drawings — confirm Div 26 spec.
A18: TELECOM OSP
A19: T1 | B19: Telecom maintenance hole MH1 | C19: 8'-0" x 96" x 96"; base 9,275 lb / top 2,100 lb | D19: Oldcastle / Jensen Precast (or regional precaster) | E19: '4260' base + top deck per H1/TSN400 | F19: TBD | G19: ='Telecom OSP'!G6 -> 4 | H19: EA | I19: '4260' designation from detail — confirm precaster & traffic rating of cover.
A20: T2 | B20: Telecom handhole HH1 | C20: 3'-0" x 24" x 48" | D20: Hubbell/Quazite or Armorcast (or equal) | E20: Polymer concrete box + slip-resistant bolted cover, ANSI Tier (non-deliberate traffic) | F20: BOD (suggested) | G20: ='Telecom OSP'!G7 -> 5 | H20: EA | I20: NOT vehicle-traffic rated per A1/TSN400 — keep out of pavement.
A21: T3 | B21: Duct bank conduit, 4" | C21: 4" PVC Type DB/EB (concrete-encased) | D21: Cantex / JM Eagle (or equal) | E21: DB-60/DB-120 PVC duct | F21: BOD (suggested) | G21: =ROUND('Telecom OSP'!G17*2+'Telecom OSP'!G20*4,0) -> 2499 | H21: LF | I21: Conduit-feet: DB1 LF x2 + DB2 LF x4 (live formula).
A22: T4 | B22: Duct bank conduit, 2" | C22: 2" PVC | D22: Cantex / JM Eagle (or equal) | E22: Sch 40/DB PVC | F22: BOD (suggested) | G22: =ROUND('Telecom OSP'!G23*2,0) -> 598 | H22: LF | I22: DB3 LF x 2 conduits (live formula).
A23: T5 | B23: Fabric innerduct, 4" 3-cell | C23: 4", 3-cell, w/ pull tapes | D23: MaxCell | E23: MaxCell 4" 3-cell (MXE4 series) | F23: Specified | G23: =ROUND('Telecom OSP'!G17*2+'Telecom OSP'!G20*4,0) -> 2499 | H23: LF | I23: 'MaxCell' named on TSN100 duct bank schedule — one per conduit.
A24: T6 | B24: Fabric innerduct, 2" 3-cell | C24: 2", 3-cell, w/ pull tapes | D24: MaxCell | E24: MaxCell 2" 3-cell (MXE2 series) | F24: Specified | G24: =ROUND('Telecom OSP'!G23*2,0) -> 598 | H24: LF | I24: One per DB3 conduit.
A25: T7 | B25: OSP fiber, 12-strand OM4 | C25: 12F OM4 50/125 MM, OSP gel-free | D25: Corning / OFS (or equal) | E25: e.g. Corning ALTOS 012TU4-T4790D20 | F25: BOD (suggested) | G25: ='Telecom OSP'!G34 -> 1600 | H25: LF | I25: Type on TSN300 is generic '12-STRAND OM4 FIBER' — exact cable per Div 27 spec.
A26: T8 | B26: Fiber termination hardware @ Bldg A | C26: 12F LC (assumed) | D26: Corning CCH / Panduit (or equal) | E26: LIU/patch panel + pigtails/splice | F26: BOD (suggested) | G26: 1 | H26: LS | I26: OTDR + IL testing per TIA; labeling per TIA-606.
A27: T9 | B27: Detectable warning tape & mule tape | C27: 6" tape @12" above duct; 1,250-lb tape | D27: Presco / Neptco (or equal) | E27: "CAUTION BURIED TELECOM" + WP1250 mule tape | F27: BOD (suggested) | G27: ='Telecom OSP'!G26 -> 1407 | H27: LF | I27: Tape LF = trench LF (live).
A28: SECURITY (Div 28 — models per spec; BOD offered where drawings silent)
A29: S1 | B29: Video intercom door/pedestal station w/ integrated reader | C29: PoE; vandal/weather resistant; flush or pedestal | D29: Aiphone (or equal) | E29: IX Series 2 (e.g. IX-DVM) + reader module | F29: BOD (suggested) | G29: 3 | H29: EA | I29: Matches 'VIC' video intercom system & extended-reach PoE copper architecture (TSY101).
A30: S2 | B30: Video intercom master station | C30: Desktop, video | D30: Aiphone (or equal) | E30: IX-MV7-* master | F30: BOD (suggested) | G30: =Security!G20 -> 1 | H30: EA | I30: Desktop mount per TSY001 schedule.
A31: S3 | B31: Gooseneck pedestal, 316 SS | C31: 48" above roadway; min 2" sq heavy wall | D31: Pedestal PRO (or equal) | E31: 316 SS gooseneck w/ template L-bolts x4 | F31: BOD (suggested) | G31: =Security!G6 -> 2 | H31: EA | I31: Welded 316 SS required by A1/TSY101; footer to frost +20" from curb.
A32: S4 | B32: Card readers | C32: Mullion/single-gang; 3'-6" AFF | D32: HID (or equal) | E32: Signo 20 / 20K | F32: BOD (suggested) | G32: =Security!G8+Security!G9 -> 2 | H32: EA | I32: Reader tech (prox/SEOS/PIV) per DOE requirements — confirm; boxes per TSY001 schedule.
A33: S5 | B33: Access control panels ACP1/ACP2 | C33: Surface mt 5'-0" AFF on fire-rated plywood | D33: LenelS2 / Software House / Mercury-based (or equal) | E33: Per Div 28 spec & DOE standard | F33: TBD | G33: =Security!G16+Security!G17 -> 2 | H33: EA | I33: Head-end platform not named on drawings — owner standard governs.
A34: S6 | B34: Gate position switch (DPS) | C34: Industrial gate switch w/ armored lead | D34: Sentrol/Edwards 2500-series (or equal) | E34: e.g. 2507A w/ magnet & bracket | F34: BOD (suggested) | G34: =Security!G12 -> 3 | H34: EA | I34: Per A7/TSY101: magnet on gate, switch on fence post, WP 1-gang box, 3/4"C to HH.
A35: S7 | B35: Vehicle exit loops | C35: Preformed loop size per operator mfr | D35: EMX / Reno A&E (or equal) | E35: Preformed loop + matching detector in operator | F35: BOD (suggested) | G35: =Security!G11 -> 3 | H35: EA | I35: Gate operators (36' cantilever slide gates per C-502/C-503) by others.
A36: S8 | B36: Extended-reach PoE copper data cable | C36: 4-pair, 22 AWG min, OSP-rated | D36: Paige (or equal) | E36: GameChanger PD2201EX (OSP) | F36: BOD (suggested) | G36: =Security!G27 -> 1400 | H36: LF | I36: Named performance (extended-reach, 22AWG, PoE) on TSY101/QC — GameChanger is the common BOD; verify E gate run length vs. mfr limit.
A37: S9 | B37: OSP access control composite cable | C37: Reader/lock/DPS/REX composite, OSP | D37: Windy City Wire / West Penn (or equal) | E37: Per Div 28 spec | F37: BOD (suggested) | G37: =Security!G26 -> 1800 | H37: LF
A38: S10 | B38: Equipment rack + SPDs | C38: 12U rack; SPDs on OSP copper & device circuits | D38: Middle Atlantic / CPI; DITEK (or equal) | E38: 12U wall rack; DTK series SPD | F38: BOD (suggested) | G38: =Security!G18 -> 1 | H38: EA | I38: Rack per G2/TSY101; SPD line item Security B8.

Sheet Assumptions
B2: ASSUMPTIONS, CLARIFICATIONS & EXCLUSIONS
B4: 1. DOCUMENTS USED
B5: Drawing set 1 | C5: DOE LM Site Improvement Package, 65% Submittal QC set, 43 sheets (Kenall project 8134, issue date Sept 02 2026) — sheets reviewed for this takeoff: G-001/002, CD101, E-001, ES101, ES601, TSN001/100/300/400, TSY001/002/100/101.
B6: Drawing set 2 | C6: Exterior Electrical/Comm QC extract, 10 sheets (ES101, ES601, TSN001/100/300/400, TSY001/002/100/101, plot date 8/25-8/26/2026). Sheets are identical in content to set 1 counterparts; tag counts verified to match in both sets.
B7: Not available | C7: Specifications (Div 26/27/28, 33 71 02), electrical one-line diagram, panel schedules, building 'A' package. Items referencing the one-line are carried as allowances; sizes marked '(assumed)' or 'TBD' pending these documents.
B9: 2. TAKEOFF METHODOLOGY
B10: Counted | C10: Device/fixture symbol and tag counts taken from plan text layer and verified visually on rendered sheets (both drawing sets agree).
B11: Dimensioned | C11: Lengths printed on TSN100 used verbatim (converted to decimal feet).
B12: Scaled | C12: Undimensioned routes measured off 150-dpi renders at the stated sheet scale 1"=30'-0" (±10% typical, ±25% for demo lines). The TSN100 graphic scale bar is wrong per QC comment ('scale bar does not match') — the title scale was used.
B13: Allowance | C13: Work that is clearly required but not yet drawn at 65% (site lighting branch circuits, security homerun cabling, OSP copper). Quantities are order-of-magnitude placeholders — revise at 95%.
B14: Sizes & types | C14: Size and Type/Material/Model columns are transcribed from the ES601 luminaire schedule, TSN100 site device & duct bank schedules, TSN400/TSY101/ES601 details, and TSY001 device schedule. Anything not stated on the drawings is marked '(assumed)' or 'TBD'.
B15: Pricing | C15: Unit costs intentionally left blank (yellow cells) for estimator input; all extensions and totals are live formulas.
B17: 3. GENERAL ASSUMPTIONS
B18: A3.1 | C18: Xcel Energy (XE) performs all primary work: boring/trenching, primary conduit & cable, transformer supply & connections, meter. Contract work starts at secondary landings + pad, grounding, meter housing (ES101 KN 4). Demarcation to be confirmed in Design Analysis (QC 11742742).
B19: A3.2 | C19: EA2 poles: plan symbol shows twin luminaire heads on a single pole; schedule lists one model. Takeoff carries 7 pole ASSEMBLIES — confirm heads/pole before pricing (14 luminaires if twin).
B20: A3.3 | C20: All 18 area-light poles are 35'-0" (schedule); foundations per 2/ES601 dimension schedule row '31'-40'' = 2'-0" dia x 9'-6" deep, 8-#5 verts.
B21: A3.4 | C21: Duct banks DB1/DB2 concrete-encased per TSN400 sections; DB3 assumed concrete-encased (no section drawn) — verify. Note the TSN100 duct bank schedule lists envelope dims (DB1 18"x10-1/2", DB2 18"x18", DB3 14"x8-1/2") that differ from the TSN400 encasement sections (23"x16", 25"x25") — encasement CY is computed from the TSN400 sections; see RFI-11.
B22: A3.5 | C22: MaxCell 3-cell fabric innerduct in EVERY duct bank conduit per TSN100 duct bank schedule (DB1/DB2: 4" cells; DB3: 2" cells) — included in duct bank unit rates.
B23: A3.6 | C23: Telecom trench: 30" min cover, below 50-yr freeze line, ≥6' below surface where vehicular traffic crosses (TSN100 GN 8/9); max 600' between MH/HH (GN 4); conduit sloped ≥0.4"/ft to MHs; 6"/12" separations from other utilities (GN 6/7).
B24: A3.7 | C24: Security homerun cabling routed through the telecom duct bank/MaxCell system to COMM 124 in Bldg A (TSY100 GN); no separate security duct bank carried. Security pathways in EMT or secured cable tray inside buildings (TSY100 GN 6).
B25: A3.8 | C25: Vehicle gates, fence, sliding/swing gate hardware are CIVIL scope (C-503); this takeoff carries only electrical/security devices, rough-in, loops and terminations at the gates.
B26: A3.9 | C26: Generator is existing government-owned; relocation + recertification testing by building electrical contractor (ES101 KN 8). Fuel, pad, and mechanical work excluded. Rating TBD from building package.
B27: A3.10 | C27: Site lighting controls are integral (PIR/dimming) + timeclock in Bldg A lighting control panel (building package); only interface wiring carried. Sequence: on 1 hr before business open, off within 1 hr after close, 10-min timeout, dim to 30%.
B28: A3.11 | C28: Assumed materials where drawings are silent: PVC Sch 40 for site branch conduits, THWN-2/XHHW-2 Cu conductors, 5/8"x8' Cu-clad ground rods, NEMA 3R/4 exterior enclosures, LC fiber terminations, 1,250-lb mule tape. All flagged '(assumed)' in the Type column.
B30: 4. EXCLUSIONS
B31: E4.1 | C31: All civil sitework: paving, grading, wet utilities (CU sheets), erosion control, fencing/gates, landscaping, flagpoles (poles themselves).
B32: E4.2 | C32: Fire protection (FP000) and all Building A/B/C interior electrical, telecom & security (building packages).
B33: E4.3 | C33: Video surveillance system (cameras, VSS server/storage, VSS cabling), intrusion detection, wireless access points, emergency blue phones — struck from TSY002 responsibility matrix at 65%. VERIFY before bid; TSY101 rack elevation still shows VSS server.
B34: E4.4 | C34: Owner-furnished items: network switches, routers/firewalls/servers/phones/computers, WAPs (TSY002/TSN001 matrices).
B35: E4.5 | C35: ISP scope: ISP fiber, ISP pedestal equipment, ISP network cabling (TSN001 matrix) — contractor provides pathway only.
B36: E4.6 | C36: Xcel Energy scope per A3.1: primary conduit/cable/trenching, transformer, meter device, existing utility transformer demolition.
B37: E4.7 | C37: Electric-service MH/HH/power poles: ES101 legend defines symbols but none appear on the 65% plan — none carried.
B38: E4.8 | C38: Hazmat survey/abatement, rock excavation, dewatering, winter conditions, premium time, taxes, bonds, escalation.
B40: 5. OPEN ITEMS / RECOMMENDED RFIs
B41: RFI-1 | C41: TSN100: overall dim 508'-8 3/4" at HH1-6 does not reconcile with segment dims (312 LF sum MH1-4→HH1-6; 435 LF from MH1-3). Confirm intended overall length / correct dims.
B42: RFI-2 | C42: DB3 duct bank: confirm concrete encasement vs. direct-bury (no section on TSN400) and confirm the partially-legible 72'-x diagonal dimension HH1-3→corner.
B43: RFI-3 | C43: Confirm EA2 = one or two luminaires per pole (plan symbol vs. schedule); complete wattage/lumen/CCT columns of luminaire schedule.
B44: RFI-4 | C44: Confirm final count/locations of card readers at swing & personnel gates (TSY101 inset vs. TSY100) and pedestrian-gate reader wall-mount change (QC).
B45: RFI-5 | C45: Confirm deletion of video surveillance & intrusion detection (TSY002 strikethroughs) vs. TSY101 rack still showing VSS server & 'to building cameras'.
B46: RFI-6 | C46: Site lighting circuiting, panel source, and photometric plan to be issued (QC) — allowances C10/C11/D2 must be re-quantified at 95%; confirm conduit/conductor sizes.
...
